submitit ERROR (2024-05-30 15:45:30,863) - Submitted job triggered an exception
Traceback (most recent call last):
  File "/home/usuaris/veu/javier.abella/anaconda3/envs/codegen_3_10/lib/python3.10/runpy.py", line 196, in _run_module_as_main
    return _run_code(code, main_globals, None,
  File "/home/usuaris/veu/javier.abella/anaconda3/envs/codegen_3_10/lib/python3.10/runpy.py", line 86, in _run_code
    exec(code, run_globals)
  File "/home/usuaris/veu/javier.abella/anaconda3/envs/codegen_3_10/lib/python3.10/site-packages/submitit/core/_submit.py", line 11, in <module>
    submitit_main()
  File "/home/usuaris/veu/javier.abella/anaconda3/envs/codegen_3_10/lib/python3.10/site-packages/submitit/core/submission.py", line 76, in submitit_main
    process_job(args.folder)
  File "/home/usuaris/veu/javier.abella/anaconda3/envs/codegen_3_10/lib/python3.10/site-packages/submitit/core/submission.py", line 69, in process_job
    raise error
  File "/home/usuaris/veu/javier.abella/anaconda3/envs/codegen_3_10/lib/python3.10/site-packages/submitit/core/submission.py", line 55, in process_job
    result = delayed.result()
  File "/home/usuaris/veu/javier.abella/anaconda3/envs/codegen_3_10/lib/python3.10/site-packages/submitit/core/utils.py", line 133, in result
    self._result = self.function(*self.args, **self.kwargs)
  File "/home/usuaris/veu/javier.abella/TFG/codegen_sources/preprocessing/bpe_modes/fast_bpe_mode.py", line 58, in learn_bpe_file
    process.returncode == 0 and Path(f"{self.codes}").is_file()
AssertionError: failed to learn bpe on /home/usuaris/veu/javier.abella/TFG/testdataset/java.sa-cl.tok.shuf.50gb.shuf, command: /home/usuaris/veu/javier.abella/TFG/fastBPE/fast learnbpe 50000 /home/usuaris/veu/javier.abella/TFG/testdataset/java.sa-cl.tok.shuf.50gb.shuf > /home/usuaris/veu/javier.abella/TFG/testdataset/java.sa-cl.codes
